Workbook

Sheet Dashboard
A1: [SCHOOL] RACING PERFORMANCE ANALYSIS | 2022-2026
A2: [SCHOOL] at FSAE Michigan (Electric) 2022-2026, plus Formula Hybrid+Electric 2026. Built from the SAE official 2026 results and the 2022-2025 data in the original workbook.
A4: 2026 MICHIGAN FINISH | D4: 2026 SCORE | G4: CHANGE VS 2025 | J4: GAP TO 2026 WINNER
A5: ="#"&'School Trend'!B10&" of "&'School Trend'!C10 -> #4 of 88 | D5: ='School Trend'!D10 -> 756.9 | G5: ='School Trend'!D10-'School Trend'!D9 -> 238.9 | J5: ='School Trend'!G10 -> -138.6
A7: YEAR BY YEAR (ranked field only)
A8: Year | B8: Place | C8: Ranked teams | D8: [SCHOOL] score | E8: Winner score | F8: Field avg | G8: Gap to winner | H8: Vs field avg | I8: Percentile | J8: Cost | K8: Design | L8: Endurance
A9: 2022 | B9: ='School Trend'!B6 -> 5 | C9: ='School Trend'!C6 -> 43 | D9: ='School Trend'!D6 -> 646 | E9: ='School Trend'!E6 -> 847 | F9: ='School Trend'!F6 -> 245.24651 | G9: ='School Trend'!G6 -> -201 | H9: ='School Trend'!J6 -> 400.75349 | I9: ='School Trend'!I6 -> 0.9047619 | J9: ='School Trend'!C15 -> 84.21 | K9: ='School Trend'!C17 -> 145 | L9: ='School Trend'!C21 -> 16
A10: 2023 | B10: ='School Trend'!B7 -> 2 | C10: ='School Trend'!C7 -> 61 | D10: ='School Trend'!D7 -> 762.4 | E10: ='School Trend'!E7 -> 919.1 | F10: ='School Trend'!F7 -> 281.08689 | G10: ='School Trend'!G7 -> -156.7 | H10: ='School Trend'!J7 -> 481.31311 | I10: ='School Trend'!I7 -> 0.98333333 | J10: ='School Trend'!D15 -> 77.4 | K10: ='School Trend'!D17 -> 113 | L10: ='School Trend'!D21 -> 226.6
A11: 2024 | B11: ='School Trend'!B8 -> 14 | C11: ='School Trend'!C8 -> 70 | D11: ='School Trend'!D8 -> 589.9 | E11: ='School Trend'!E8 -> 760.6 | F11: ='School Trend'!F8 -> 323.39714 | G11: ='School Trend'!G8 -> -170.7 | H11: ='School Trend'!J8 -> 266.50286 | I11: ='School Trend'!I8 -> 0.8115942 | J11: ='School Trend'!E15 -> 51 | K11: ='School Trend'!E17 -> 75 | L11: ='School Trend'!E21 -> 186.5
A12: 2025 | B12: ='School Trend'!B9 -> 13 | C12: ='School Trend'!C9 -> 78 | D12: ='School Trend'!D9 -> 518 | E12: ='School Trend'!E9 -> 790.4 | F12: ='School Trend'!F9 -> 279.86923 | G12: ='School Trend'!G9 -> -272.4 | H12: ='School Trend'!J9 -> 238.13077 | I12: ='School Trend'!I9 -> 0.84415584 | J12: ='School Trend'!F15 -> 90.22 | K12: ='School Trend'!F17 -> 130 | L12: ='School Trend'!F21 -> 21
A13: 2026 | B13: ='School Trend'!B10 -> 4 | C13: ='School Trend'!C10 -> 88 | D13: ='School Trend'!D10 -> 756.9 | E13: ='School Trend'!E10 -> 895.5 | F13: ='School Trend'!F10 -> 298.65795 | G13: ='School Trend'!G10 -> -138.6 | H13: ='School Trend'!J10 -> 458.24205 | I13: ='School Trend'!I10 -> 0.96551724 | J13: ='School Trend'!G15 -> 98 | K13: ='School Trend'!G17 -> 143 | L13: ='School Trend'!G21 -> 186.2
A15: KEY TAKEAWAYS (numbers computed from the data)
A16: 1. 2026 was [SCHOOL]'s best Michigan finish since 2023: 4th of 88 with 756.9 pts, up 238.9 pts (46.1%) from 2025.
A17: 2. Cost was 1st of 85 teams at Michigan 2026 (98.0 pts). Design was 4th and acceleration 5th.
A18: 3. Biggest points left on the table in 2026: endurance (88.8 of 275 missed), presentation (44.8 of 75 missed, 46th of 108 entries with a score) and efficiency (58.6 of 100 missed).
A19: 4. Gap to the winner shrank from 272.4 pts in 2025 to 138.6 pts in 2026 (winner: Oregon State Univ, 895.5).
A20: 5. Formula Hybrid+Electric 2026: [SCHOOL] won the electric class (organizer results). Separate competition with its own scoring, so points are not compared with Michigan.
A21: Verification status: 2026 figures were checked row by row against the SAE official results PDF. 2022 and 2025 places and totals were checked against the official PDFs, 2023 and 2024 against FS World. 2023-2024 specs are unverified. See Data Quality and Sources & Notes.

Sheet School Trend
A1: [SCHOOL] TREND | MICHIGAN ELECTRIC 2022-2026
A2: Formulas read from Results Data. Field = ranked teams only (teams with a numeric overall place).
A4: YEARLY TOTALS
A5: Year | B5: Place | C5: Ranked teams | D5: [SCHOOL] score | E5: Winner score | F5: Field avg | G5: Gap to winner | H5: [SCHOOL] / winner | I5: Percentile | J5: Vs field avg | K5: Field median | L5: Winner | M5: 10th-place score
A6: 2022 | B6: =SUMIFS('Results Data'!$B$4:$B$418,'Results Data'!$A$4:$A$418,A6,'Results Data'!$S$4:$S$418,1) -> 5 | C6: =COUNTIFS('Results Data'!$A$4:$A$418,A6,'Results Data'!$P$4:$P$418,1) -> 43 | D6: =SUMIFS('Results Data'!$E$4:$E$418,'Results Data'!$A$4:$A$418,A6,'Results Data'!$S$4:$S$418,1) -> 646 | E6: =_xlfn.MAXIFS('Results Data'!$E$4:$E$418,'Results Data'!$A$4:$A$418,A6,'Results Data'!$P$4:$P$418,1) -> 847 | F6: =AVERAGEIFS('Results Data'!$E$4:$E$418,'Results Data'!$A$4:$A$418,A6,'Results Data'!$P$4:$P$418,1) -> 245.24651 | G6: =D6-E6 -> -201 | H6: =D6/E6 -> 0.76269185 | I6: =1-(B6-1)/(C6-1) -> 0.9047619 | J6: =D6-F6 -> 400.75349 | K6: 178.2 | L6: Ecole Polytechnique Montreal | M6: 272.3
A7: 2023 | B7: =SUMIFS('Results Data'!$B$4:$B$418,'Results Data'!$A$4:$A$418,A7,'Results Data'!$S$4:$S$418,1) -> 2 | C7: =COUNTIFS('Results Data'!$A$4:$A$418,A7,'Results Data'!$P$4:$P$418,1) -> 61 | D7: =SUMIFS('Results Data'!$E$4:$E$418,'Results Data'!$A$4:$A$418,A7,'Results Data'!$S$4:$S$418,1) -> 762.4 | E7: =_xlfn.MAXIFS('Results Data'!$E$4:$E$418,'Results Data'!$A$4:$A$418,A7,'Results Data'!$P$4:$P$418,1) -> 919.1 | F7: =AVERAGEIFS('Results Data'!$E$4:$E$418,'Results Data'!$A$4:$A$418,A7,'Results Data'!$P$4:$P$418,1) -> 281.08689 | G7: =D7-E7 -> -156.7 | H7: =D7/E7 -> 0.82950713 | I7: =1-(B7-1)/(C7-1) -> 0.98333333 | J7: =D7-F7 -> 481.31311 | K7: 190.6 | L7: Ecole de Technologie Superieure | M7: 545.1
A8: 2024 | B8: =SUMIFS('Results Data'!$B$4:$B$418,'Results Data'!$A$4:$A$418,A8,'Results Data'!$S$4:$S$418,1) -> 14 | C8: =COUNTIFS('Results Data'!$A$4:$A$418,A8,'Results Data'!$P$4:$P$418,1) -> 70 | D8: =SUMIFS('Results Data'!$E$4:$E$418,'Results Data'!$A$4:$A$418,A8,'Results Data'!$S$4:$S$418,1) -> 589.9 | E8: =_xlfn.MAXIFS('Results Data'!$E$4:$E$418,'Results Data'!$A$4:$A$418,A8,'Results Data'!$P$4:$P$418,1) -> 760.6 | F8: =AVERAGEIFS('Results Data'!$E$4:$E$418,'Results Data'!$A$4:$A$418,A8,'Results Data'!$P$4:$P$418,1) -> 323.39714 | G8: =D8-E8 -> -170.7 | H8: =D8/E8 -> 0.77557192 | I8: =1-(B8-1)/(C8-1) -> 0.8115942 | J8: =D8-F8 -> 266.50286 | K8: 218.8 | L8: Rochester Institute of Technology | M8: 682.7
A9: 2025 | B9: =SUMIFS('Results Data'!$B$4:$B$418,'Results Data'!$A$4:$A$418,A9,'Results Data'!$S$4:$S$418,1) -> 13 | C9: =COUNTIFS('Results Data'!$A$4:$A$418,A9,'Results Data'!$P$4:$P$418,1) -> 78 | D9: =SUMIFS('Results Data'!$E$4:$E$418,'Results Data'!$A$4:$A$418,A9,'Results Data'!$S$4:$S$418,1) -> 518 | E9: =_xlfn.MAXIFS('Results Data'!$E$4:$E$418,'Results Data'!$A$4:$A$418,A9,'Results Data'!$P$4:$P$418,1) -> 790.4 | F9: =AVERAGEIFS('Results Data'!$E$4:$E$418,'Results Data'!$A$4:$A$418,A9,'Results Data'!$P$4:$P$418,1) -> 279.86923 | G9: =D9-E9 -> -272.4 | H9: =D9/E9 -> 0.65536437 | I9: =1-(B9-1)/(C9-1) -> 0.84415584 | J9: =D9-F9 -> 238.13077 | K9: 196.9 | L9: Oregon State Univ | M9: 593
A10: 2026 | B10: =SUMIFS('Results Data'!$B$4:$B$418,'Results Data'!$A$4:$A$418,A10,'Results Data'!$S$4:$S$418,1) -> 4 | C10: =COUNTIFS('Results Data'!$A$4:$A$418,A10,'Results Data'!$P$4:$P$418,1) -> 88 | D10: =SUMIFS('Results Data'!$E$4:$E$418,'Results Data'!$A$4:$A$418,A10,'Results Data'!$S$4:$S$418,1) -> 756.9 | E10: =_xlfn.MAXIFS('Results Data'!$E$4:$E$418,'Results Data'!$A$4:$A$418,A10,'Results Data'!$P$4:$P$418,1) -> 895.5 | F10: =AVERAGEIFS('Results Data'!$E$4:$E$418,'Results Data'!$A$4:$A$418,A10,'Results Data'!$P$4:$P$418,1) -> 298.65795 | G10: =D10-E10 -> -138.6 | H10: =D10/E10 -> 0.84522613 | I10: =1-(B10-1)/(C10-1) -> 0.96551724 | J10: =D10-F10 -> 458.24205 | K10: 221.8 | L10: Oregon State Univ | M10: 671.3
A11: Median and 10th-place score are computed from Results Data (static values). Percentile = 1 - (place - 1) / (ranked teams - 1); first place = 100%.
A13: EVENT POINTS BY YEAR ([SCHOOL])
A14: Event | B14: Max pts | C14: 2022 | D14: 2023 | E14: 2024 | F14: 2025 | G14: 2026 | H14: Best year
A15: Cost | B15: 100 | C15: =SUMIFS('Results Data'!$F$4:$F$418,'Results Data'!$A$4:$A$418,2022,'Results Data'!$S$4:$S$418,1) -> 84.21 | D15: =SUMIFS('Results Data'!$F$4:$F$418,'Results Data'!$A$4:$A$418,2023,'Results Data'!$S$4:$S$418,1) -> 77.4 | E15: =SUMIFS('Results Data'!$F$4:$F$418,'Results Data'!$A$4:$A$418,2024,'Results Data'!$S$4:$S$418,1) -> 51 | F15: =SUMIFS('Results Data'!$F$4:$F$418,'Results Data'!$A$4:$A$418,2025,'Results Data'!$S$4:$S$418,1) -> 90.22 | G15: =SUMIFS('Results Data'!$F$4:$F$418,'Results Data'!$A$4:$A$418,2026,'Results Data'!$S$4:$S$418,1) -> 98 | H15: =INDEX($C$14:$G$14,MATCH(MAX(C15:G15),C15:G15,0)) -> 2026
A16: Presentation | B16: 75 | C16: =SUMIFS('Results Data'!$G$4:$G$418,'Results Data'!$A$4:$A$418,2022,'Results Data'!$S$4:$S$418,1) -> 73.8 | D16: =SUMIFS('Results Data'!$G$4:$G$418,'Results Data'!$A$4:$A$418,2023,'Results Data'!$S$4:$S$418,1) -> 49.5 | E16: =SUMIFS('Results Data'!$G$4:$G$418,'Results Data'!$A$4:$A$418,2024,'Results Data'!$S$4:$S$418,1) -> 61.8 | F16: =SUMIFS('Results Data'!$G$4:$G$418,'Results Data'!$A$4:$A$418,2025,'Results Data'!$S$4:$S$418,1) -> 49.9 | G16: =SUMIFS('Results Data'!$G$4:$G$418,'Results Data'!$A$4:$A$418,2026,'Results Data'!$S$4:$S$418,1) -> 30.2 | H16: =INDEX($C$14:$G$14,MATCH(MAX(C16:G16),C16:G16,0)) -> 2022
A17: Design | B17: 150 | C17: =SUMIFS('Results Data'!$H$4:$H$418,'Results Data'!$A$4:$A$418,2022,'Results Data'!$S$4:$S$418,1) -> 145 | D17: =SUMIFS('Results Data'!$H$4:$H$418,'Results Data'!$A$4:$A$418,2023,'Results Data'!$S$4:$S$418,1) -> 113 | E17: =SUMIFS('Results Data'!$H$4:$H$418,'Results Data'!$A$4:$A$418,2024,'Results Data'!$S$4:$S$418,1) -> 75 | F17: =SUMIFS('Results Data'!$H$4:$H$418,'Results Data'!$A$4:$A$418,2025,'Results Data'!$S$4:$S$418,1) -> 130 | G17: =SUMIFS('Results Data'!$H$4:$H$418,'Results Data'!$A$4:$A$418,2026,'Results Data'!$S$4:$S$418,1) -> 143 | H17: =INDEX($C$14:$G$14,MATCH(MAX(C17:G17),C17:G17,0)) -> 2022
A18: Accel | B18: 100 | C18: =SUMIFS('Results Data'!$I$4:$I$418,'Results Data'!$A$4:$A$418,2022,'Results Data'!$S$4:$S$418,1) -> 91.35 | D18: =SUMIFS('Results Data'!$I$4:$I$418,'Results Data'!$A$4:$A$418,2023,'Results Data'!$S$4:$S$418,1) -> 66.29 | E18: =SUMIFS('Results Data'!$I$4:$I$418,'Results Data'!$A$4:$A$418,2024,'Results Data'!$S$4:$S$418,1) -> 51.64 | F18: =SUMIFS('Results Data'!$I$4:$I$418,'Results Data'!$A$4:$A$418,2025,'Results Data'!$S$4:$S$418,1) -> 81.34 | G18: =SUMIFS('Results Data'!$I$4:$I$418,'Results Data'!$A$4:$A$418,2026,'Results Data'!$S$4:$S$418,1) -> 93.7 | H18: =INDEX($C$14:$G$14,MATCH(MAX(C18:G18),C18:G18,0)) -> 2026
A19: Skid Pad | B19: 75 | C19: =SUMIFS('Results Data'!$J$4:$J$418,'Results Data'!$A$4:$A$418,2022,'Results Data'!$S$4:$S$418,1) -> 48.48 | D19: =SUMIFS('Results Data'!$J$4:$J$418,'Results Data'!$A$4:$A$418,2023,'Results Data'!$S$4:$S$418,1) -> 47.18 | E19: =SUMIFS('Results Data'!$J$4:$J$418,'Results Data'!$A$4:$A$418,2024,'Results Data'!$S$4:$S$418,1) -> 50.53 | F19: =SUMIFS('Results Data'!$J$4:$J$418,'Results Data'!$A$4:$A$418,2025,'Results Data'!$S$4:$S$418,1) -> 56.45 | G19: =SUMIFS('Results Data'!$J$4:$J$418,'Results Data'!$A$4:$A$418,2026,'Results Data'!$S$4:$S$418,1) -> 55 | H19: =INDEX($C$14:$G$14,MATCH(MAX(C19:G19),C19:G19,0)) -> 2025
A20: Autocross | B20: 125 | C20: =SUMIFS('Results Data'!$K$4:$K$418,'Results Data'!$A$4:$A$418,2022,'Results Data'!$S$4:$S$418,1) -> 92.17 | D20: =SUMIFS('Results Data'!$K$4:$K$418,'Results Data'!$A$4:$A$418,2023,'Results Data'!$S$4:$S$418,1) -> 91.05 | E20: =SUMIFS('Results Data'!$K$4:$K$418,'Results Data'!$A$4:$A$418,2024,'Results Data'!$S$4:$S$418,1) -> 79.22 | F20: =SUMIFS('Results Data'!$K$4:$K$418,'Results Data'!$A$4:$A$418,2025,'Results Data'!$S$4:$S$418,1) -> 89.03 | G20: =SUMIFS('Results Data'!$K$4:$K$418,'Results Data'!$A$4:$A$418,2026,'Results Data'!$S$4:$S$418,1) -> 109.4 | H20: =INDEX($C$14:$G$14,MATCH(MAX(C20:G20),C20:G20,0)) -> 2026
A21: Endurance | B21: 275 | C21: =SUMIFS('Results Data'!$L$4:$L$418,'Results Data'!$A$4:$A$418,2022,'Results Data'!$S$4:$S$418,1) -> 16 | D21: =SUMIFS('Results Data'!$L$4:$L$418,'Results Data'!$A$4:$A$418,2023,'Results Data'!$S$4:$S$418,1) -> 226.6 | E21: =SUMIFS('Results Data'!$L$4:$L$418,'Results Data'!$A$4:$A$418,2024,'Results Data'!$S$4:$S$418,1) -> 186.5 | F21: =SUMIFS('Results Data'!$L$4:$L$418,'Results Data'!$A$4:$A$418,2025,'Results Data'!$S$4:$S$418,1) -> 21 | G21: =SUMIFS('Results Data'!$L$4:$L$418,'Results Data'!$A$4:$A$418,2026,'Results Data'!$S$4:$S$418,1) -> 186.2 | H21: =INDEX($C$14:$G$14,MATCH(MAX(C21:G21),C21:G21,0)) -> 2023
A22: Efficiency | B22: 100 | C22: =SUMIFS('Results Data'!$M$4:$M$418,'Results Data'!$A$4:$A$418,2022,'Results Data'!$S$4:$S$418,1) -> 95 | D22: =SUMIFS('Results Data'!$M$4:$M$418,'Results Data'!$A$4:$A$418,2023,'Results Data'!$S$4:$S$418,1) -> 91.4 | E22: =SUMIFS('Results Data'!$M$4:$M$418,'Results Data'!$A$4:$A$418,2024,'Results Data'!$S$4:$S$418,1) -> 34.3 | F22: =SUMIFS('Results Data'!$M$4:$M$418,'Results Data'!$A$4:$A$418,2025,'Results Data'!$S$4:$S$418,1) -> 0 | G22: =SUMIFS('Results Data'!$M$4:$M$418,'Results Data'!$A$4:$A$418,2026,'Results Data'!$S$4:$S$418,1) -> 41.4 | H22: =INDEX($C$14:$G$14,MATCH(MAX(C22:G22),C22:G22,0)) -> 2022
A24: EVENT SCORE AS % OF MAX POINTS (chart data)
A25: Event | C25: 2022 | D25: 2023 | E25: 2024 | F25: 2025 | G25: 2026
A26: Cost | C26: =C15/$B15 -> 0.8421 | D26: =D15/$B15 -> 0.774 | E26: =E15/$B15 -> 0.51 | F26: =F15/$B15 -> 0.9022 | G26: =G15/$B15 -> 0.98
A27: Presentation | C27: =C16/$B16 -> 0.984 | D27: =D16/$B16 -> 0.66 | E27: =E16/$B16 -> 0.824 | F27: =F16/$B16 -> 0.66533333 | G27: =G16/$B16 -> 0.40266667
A28: Design | C28: =C17/$B17 -> 0.96666667 | D28: =D17/$B17 -> 0.75333333 | E28: =E17/$B17 -> 0.5 | F28: =F17/$B17 -> 0.86666667 | G28: =G17/$B17 -> 0.95333333
A29: Accel | C29: =C18/$B18 -> 0.9135 | D29: =D18/$B18 -> 0.6629 | E29: =E18/$B18 -> 0.5164 | F29: =F18/$B18 -> 0.8134 | G29: =G18/$B18 -> 0.937
A30: Skid Pad | C30: =C19/$B19 -> 0.6464 | D30: =D19/$B19 -> 0.62906667 | E30: =E19/$B19 -> 0.67373333 | F30: =F19/$B19 -> 0.75266667 | G30: =G19/$B19 -> 0.73333333
A31: Autocross | C31: =C20/$B20 -> 0.73736 | D31: =D20/$B20 -> 0.7284 | E31: =E20/$B20 -> 0.63376 | F31: =F20/$B20 -> 0.71224 | G31: =G20/$B20 -> 0.8752
A32: Endurance | C32: =C21/$B21 -> 0.058181818 | D32: =D21/$B21 -> 0.824 | E32: =E21/$B21 -> 0.67818182 | F32: =F21/$B21 -> 0.076363636 | G32: =G21/$B21 -> 0.67709091
A33: Efficiency | C33: =C22/$B22 -> 0.95 | D33: =D22/$B22 -> 0.914 | E33: =E22/$B22 -> 0.343 | F33: =F22/$B22 -> 0 | G33: =G22/$B22 -> 0.414
A35: 2025 Efficiency shows 0%: [SCHOOL] did not score in the efficiency event that year (DNS in the source data).

Sheet Event Deep Dive
A1: EVENT DEEP DIVE | [SCHOOL] RANK IN EVERY EVENT
A2: Rank = 1 + number of teams with a higher score, among teams that scored above 0 in that event. Event data for 2022 is partial in the source, so 2022 ranks are less reliable.
A4: 2022 | [SCHOOL] placed #5 of 43 ranked teams | 646.0 pts
A5: Event | B5: Max pts | C5: [SCHOOL] score | D5: % of max | E5: [SCHOOL] rank | F5: Teams scored | G5: Rank percentile | H5: Field avg (scored) | I5: Field best (team) | J5: [SCHOOL] site rank
A6: Cost | B6: 100 | C6: 84.21 | D6: =C6/B6 -> 0.8421 | E6: 6 | F6: 36 | G6: =1-(E6-1)/(F6-1) -> 0.85714286 | H6: 62.1 | I6: 90.9 (McGill Univ) | J6: 6
A7: Presentation | B7: 75 | C7: 73.8 | D7: =C7/B7 -> 0.984 | E7: 2 | F7: 56 | G7: =1-(E7-1)/(F7-1) -> 0.98181818 | H7: 59.6 | I7: 75.0 (Ryerson Univ) | J7: 2
A8: Design | B8: 150 | C8: 145 | D8: =C8/B8 -> 0.96666667 | E8: 2 | F8: 40 | G8: =1-(E8-1)/(F8-1) -> 0.97435897 | H8: 75.6 | I8: 150.0 (Ecole De Technologie Sup) | J8: 2
A9: Accel | B9: 100 | C9: 91.35 | D9: =C9/B9 -> 0.9135 | E9: 4 | F9: 6 | G9: =1-(E9-1)/(F9-1) -> 0.4 | H9: 79.6 | I9: 100.0 (Oregon State Univ) | J9: 5
A10: Skid Pad | B10: 75 | C10: 48.48 | D10: =C10/B10 -> 0.6464 | E10: 5 | F10: 8 | G10: =1-(E10-1)/(F10-1) -> 0.5 | H10: 45.9 | I10: 75.0 (Univ of Michigan - Ann A) | J10: 5
A11: Autocross | B11: 125 | C11: 92.17 | D11: =C11/B11 -> 0.73736 | E11: 5 | F11: 8 | G11: =1-(E11-1)/(F11-1) -> 0.42857143 | H11: 77.3 | I11: 125.0 (Oregon State Univ) | J11: 6
A12: Endurance | B12: 275 | C12: 16 | D12: =C12/B12 -> 0.058181818 | E12: 8 | F12: 11 | G12: =1-(E12-1)/(F12-1) -> 0.3 | H12: 63.1 | I12: 275.0 (Ecole Polytechnique Mont) | J12: 7
A13: Efficiency | B13: 100 | C13: 95 | D13: =C13/B13 -> 0.95 | E13: 3 | F13: 7 | G13: =1-(E13-1)/(F13-1) -> 0.66666667 | H13: 93 | I13: 100.0 (Univ of Texas - Austin) | J13: -
A15: 2023 | [SCHOOL] placed #2 of 61 ranked teams | 762.4 pts
A16: Event | B16: Max pts | C16: [SCHOOL] score | D16: % of max | E16: [SCHOOL] rank | F16: Teams scored | G16: Rank percentile | H16: Field avg (scored) | I16: Field best (team) | J16: [SCHOOL] site rank
A17: Cost | B17: 100 | C17: 77.4 | D17: =C17/B17 -> 0.774 | E17: 18 | F17: 61 | G17: =1-(E17-1)/(F17-1) -> 0.71666667 | H17: 62.8 | I17: 99.0 (Kennesaw State Universit) | J17: 18
A18: Presentation | B18: 75 | C18: 49.5 | D18: =C18/B18 -> 0.66 | E18: 31 | F18: 68 | G18: =1-(E18-1)/(F18-1) -> 0.55223881 | H18: 48.2 | I18: 75.0 (Toronto Metropolitan Uni) | J18: 32
A19: Design | B19: 150 | C19: 113 | D19: =C19/B19 -> 0.75333333 | E19: 8 | F19: 61 | G19: =1-(E19-1)/(F19-1) -> 0.88333333 | H19: 72.6 | I19: 150.0 (McGill Univ) | J19: 8
A20: Accel | B20: 100 | C20: 66.29 | D20: =C20/B20 -> 0.6629 | E20: 4 | F20: 13 | G20: =1-(E20-1)/(F20-1) -> 0.76923077 | H20: 51.2 | I20: 100.0 (Georgia Institute of Tec) | J20: 4
A21: Skid Pad | B21: 75 | C21: 47.18 | D21: =C21/B21 -> 0.62906667 | E21: 3 | F21: 20 | G21: =1-(E21-1)/(F21-1) -> 0.9 | H21: 32.7 | I21: 75.0 (Georgia Institute of Tec) | J21: 3
A22: Autocross | B22: 125 | C22: 91.05 | D22: =C22/B22 -> 0.7284 | E22: 8 | F22: 21 | G22: =1-(E22-1)/(F22-1) -> 0.65 | H22: 74 | I22: 125.0 (Ecole de Technologie Sup) | J22: 8
A23: Endurance | B23: 275 | C23: 226.6 | D23: =C23/B23 -> 0.824 | E23: 3 | F23: 21 | G23: =1-(E23-1)/(F23-1) -> 0.9 | H23: 103.3 | I23: 275.0 (Ecole de Technologie Sup) | J23: 3
A24: Efficiency | B24: 100 | C24: 91.4 | D24: =C24/B24 -> 0.914 | E24: 5 | F24: 14 | G24: =1-(E24-1)/(F24-1) -> 0.69230769 | H24: 90.6 | I24: 100.0 (Univ of Texas - Arlingto) | J24: -
A26: 2024 | [SCHOOL] placed #14 of 70 ranked teams | 589.9 pts
A27: Event | B27: Max pts | C27: [SCHOOL] score | D27: % of max | E27: [SCHOOL] rank | F27: Teams scored | G27: Rank percentile | H27: Field avg (scored) | I27: Field best (team) | J27: [SCHOOL] site rank
A28: Cost | B28: 100 | C28: 51 | D28: =C28/B28 -> 0.51 | E28: 48 | F28: 68 | G28: =1-(E28-1)/(F28-1) -> 0.29850746 | H28: 61.1 | I28: 96.9 (Kennesaw State Universit) | J28: 48
A29: Presentation | B29: 75 | C29: 61.8 | D29: =C29/B29 -> 0.824 | E29: 12 | F29: 77 | G29: =1-(E29-1)/(F29-1) -> 0.85526316 | H29: 45.2 | I29: 75.0 (Kennesaw State Universit) | J29: 12
A30: Design | B30: 150 | C30: 75 | D30: =C30/B30 -> 0.5 | E30: 32 | F30: 70 | G30: =1-(E30-1)/(F30-1) -> 0.55072464 | H30: 75.9 | I30: 150.0 (McGill Univ) | J30: 32
A31: Accel | B31: 100 | C31: 51.64 | D31: =C31/B31 -> 0.5164 | E31: 8 | F31: 31 | G31: =1-(E31-1)/(F31-1) -> 0.78125 | H31: 36.6 | I31: 100.0 (Georgia Institute of Tec) | J31: 8
A32: Skid Pad | B32: 75 | C32: 50.53 | D32: =C32/B32 -> 0.67373333 | E32: 9 | F32: 32 | G32: =1-(E32-1)/(F32-1) -> 0.75 | H32: 40.1 | I32: 75.0 (Georgia Institute of Tec) | J32: 9
A33: Autocross | B33: 125 | C33: 79.22 | D33: =C33/B33 -> 0.63376 | E33: 19 | F33: 28 | G33: =1-(E33-1)/(F33-1) -> 0.41935484 | H33: 85.7 | I33: 125.0 (Georgia Institute of Tec) | J33: 19
A34: Endurance | B34: 275 | C34: 186.5 | D34: =C34/B34 -> 0.67818182 | E34: 13 | F34: 36 | G34: =1-(E34-1)/(F34-1) -> 0.65714286 | H34: 120.2 | I34: 275.0 (Univ of Washington) | J34: 13
A35: Efficiency | B35: 100 | C35: 34.3 | D35: =C35/B35 -> 0.343 | E35: 18 | F35: 21 | G35: =1-(E35-1)/(F35-1) -> 0.15 | H35: 50.3 | I35: 100.0 (Cornell Univ) | J35: -
A37: 2025 | [SCHOOL] placed #13 of 78 ranked teams | 518.0 pts
A38: Event | B38: Max pts | C38: [SCHOOL] score | D38: % of max | E38: [SCHOOL] rank | F38: Teams scored | G38: Rank percentile | H38: Field avg (scored) | I38: Field best (team) | J38: [SCHOOL] site rank
A39: Cost | B39: 100 | C39: 90.22 | D39: =C39/B39 -> 0.9022 | E39: 2 | F39: 76 | G39: =1-(E39-1)/(F39-1) -> 0.98666667 | H39: 63.9 | I39: 90.4 (Univ of Pennsylvania) | J39: 2
A40: Presentation | B40: 75 | C40: 49.9 | D40: =C40/B40 -> 0.66533333 | E40: 29 | F40: 99 | G40: =1-(E40-1)/(F40-1) -> 0.71428571 | H40: 33.6 | I40: 75.0 (Rochester Institute of T) | J40: 29
A41: Design | B41: 150 | C41: 130 | D41: =C41/B41 -> 0.86666667 | E41: 3 | F41: 79 | G41: =1-(E41-1)/(F41-1) -> 0.97435897 | H41: 80.1 | I41: 150.0 (Univ of Wisconsin - Madi) | J41: 3
A42: Accel | B42: 100 | C42: 81.34 | D42: =C42/B42 -> 0.8134 | E42: 6 | F42: 26 | G42: =1-(E42-1)/(F42-1) -> 0.80769231 | H42: 55.8 | I42: 100.0 (Georgia Institute of Tec) | J42: 6
A43: Skid Pad | B43: 75 | C43: 56.45 | D43: =C43/B43 -> 0.75266667 | E43: 9 | F43: 27 | G43: =1-(E43-1)/(F43-1) -> 0.7037037 | H43: 47.1 | I43: 75.0 (Oregon State Univ) | J43: 9
A44: Autocross | B44: 125 | C44: 89.03 | D44: =C44/B44 -> 0.71224 | E44: 16 | F44: 26 | G44: =1-(E44-1)/(F44-1) -> 0.44444444 | H44: 84.1 | I44: 125.0 (Univ of Washington) | J44: 16
...

Sheet Field Overview
A1: FIELD OVERVIEW | HOW STRONG WAS THE FIELD?
A2: Statistics use ranked teams only. Counts, winner, average from live formulas; median, spread and cutoffs computed from Results Data.
A4: FIELD STATISTICS BY YEAR
A5: Year | B5: Ranked teams | C5: Winner score | D5: Field avg | E5: Field median | F5: Std dev | G5: 10th place | H5: [SCHOOL] score | I5: [SCHOOL] place | J5: [SCHOOL] vs median | K5: Winner | L5: Entries incl. unranked
A6: 2022 | B6: =COUNTIFS('Results Data'!$A$4:$A$418,A6,'Results Data'!$P$4:$P$418,1) -> 43 | C6: =_xlfn.MAXIFS('Results Data'!$E$4:$E$418,'Results Data'!$A$4:$A$418,A6,'Results Data'!$P$4:$P$418,1) -> 847 | D6: =AVERAGEIFS('Results Data'!$E$4:$E$418,'Results Data'!$A$4:$A$418,A6,'Results Data'!$P$4:$P$418,1) -> 245.24651 | E6: 178.2 | F6: 197.1 | G6: 272.3 | H6: ='School Trend'!D6 -> 646 | I6: ='School Trend'!B6 -> 5 | J6: =H6-E6 -> 467.8 | K6: Ecole Polytechnique Montreal | L6: 58
A7: 2023 | B7: =COUNTIFS('Results Data'!$A$4:$A$418,A7,'Results Data'!$P$4:$P$418,1) -> 61 | C7: =_xlfn.MAXIFS('Results Data'!$E$4:$E$418,'Results Data'!$A$4:$A$418,A7,'Results Data'!$P$4:$P$418,1) -> 919.1 | D7: =AVERAGEIFS('Results Data'!$E$4:$E$418,'Results Data'!$A$4:$A$418,A7,'Results Data'!$P$4:$P$418,1) -> 281.08689 | E7: 190.6 | F7: 208 | G7: 545.1 | H7: ='School Trend'!D7 -> 762.4 | I7: ='School Trend'!B7 -> 2 | J7: =H7-E7 -> 571.8 | K7: Ecole de Technologie Superieure | L7: 69
A8: 2024 | B8: =COUNTIFS('Results Data'!$A$4:$A$418,A8,'Results Data'!$P$4:$P$418,1) -> 70 | C8: =_xlfn.MAXIFS('Results Data'!$E$4:$E$418,'Results Data'!$A$4:$A$418,A8,'Results Data'!$P$4:$P$418,1) -> 760.6 | D8: =AVERAGEIFS('Results Data'!$E$4:$E$418,'Results Data'!$A$4:$A$418,A8,'Results Data'!$P$4:$P$418,1) -> 323.39714 | E8: 218.8 | F8: 226.8 | G8: 682.7 | H8: ='School Trend'!D8 -> 589.9 | I8: ='School Trend'!B8 -> 14 | J8: =H8-E8 -> 371.1 | K8: Rochester Institute of Technology | L8: 79
A9: 2025 | B9: =COUNTIFS('Results Data'!$A$4:$A$418,A9,'Results Data'!$P$4:$P$418,1) -> 78 | C9: =_xlfn.MAXIFS('Results Data'!$E$4:$E$418,'Results Data'!$A$4:$A$418,A9,'Results Data'!$P$4:$P$418,1) -> 790.4 | D9: =AVERAGEIFS('Results Data'!$E$4:$E$418,'Results Data'!$A$4:$A$418,A9,'Results Data'!$P$4:$P$418,1) -> 279.86923 | E9: 196.9 | F9: 212.7 | G9: 593 | H9: ='School Trend'!D9 -> 518 | I9: ='School Trend'!B9 -> 13 | J9: =H9-E9 -> 321.1 | K9: Oregon State Univ | L9: 101
A10: 2026 | B10: =COUNTIFS('Results Data'!$A$4:$A$418,A10,'Results Data'!$P$4:$P$418,1) -> 88 | C10: =_xlfn.MAXIFS('Results Data'!$E$4:$E$418,'Results Data'!$A$4:$A$418,A10,'Results Data'!$P$4:$P$418,1) -> 895.5 | D10: =AVERAGEIFS('Results Data'!$E$4:$E$418,'Results Data'!$A$4:$A$418,A10,'Results Data'!$P$4:$P$418,1) -> 298.65795 | E10: 221.8 | F10: 215.3 | G10: 671.3 | H10: ='School Trend'!D10 -> 756.9 | I10: ='School Trend'!B10 -> 4 | J10: =H10-E10 -> 535.1 | K10: Oregon State Univ | L10: 108
A11: 2025: the original workbook listed 80 active teams but only 78 had a numeric overall place, so 78 is used. 2026: 88 ranked finishers plus 20 presentation-only entries (not ranked, excluded from the field).
A13: ENDURANCE SCORING RATE | how many teams actually finished laps
A14: Year | B14: Ranked teams | C14: Teams with endurance pts | D14: Scoring rate | E14: Avg (scored) | F14: Median (scored) | G14: Best | H14: [SCHOOL] endurance | I14: [SCHOOL] vs avg
A15: 2022 | B15: 43 | C15: 11 | D15: =C15/B15 -> 0.25581395 | E15: 63.1 | F15: 25 | G15: 275 | H15: 16 | I15: =H15-E15 -> -47.1
A16: 2023 | B16: 61 | C16: 21 | D16: =C16/B16 -> 0.3442623 | E16: 103.3 | F16: 55.5 | G16: 275 | H16: 226.6 | I16: =H16-E16 -> 123.3
A17: 2024 | B17: 70 | C17: 36 | D17: =C17/B17 -> 0.51428571 | E17: 120.2 | F17: 137.3 | G17: 275 | H17: 186.5 | I17: =H17-E17 -> 66.3
A18: 2025 | B18: 78 | C18: 30 | D18: =C18/B18 -> 0.38461538 | E18: 84.1 | F18: 25 | G18: 275 | H18: 21 | I18: =H18-E18 -> -63.1
A19: 2026 | B19: 88 | C19: 39 | D19: =C19/B19 -> 0.44318182 | E19: 84.7 | F19: 25 | G19: 275 | H19: 186.2 | I19: =H19-E19 -> 101.5
A21: EVENT AVERAGES | field average per event (teams that scored) and [SCHOOL] difference
A22: Event | B22: Max | C22: 2022 avg | D22: 2023 avg | E22: 2024 avg | F22: 2025 avg | G22: 2026 avg | H22: [SCHOOL] 2022 vs avg | I22: [SCHOOL] 2023 vs avg | J22: [SCHOOL] 2024 vs avg | K22: [SCHOOL] 2025 vs avg | L22: [SCHOOL] 2026 vs avg
A23: Cost | B23: 100 | C23: 62.1 | D23: 62.8 | E23: 61.1 | F23: 64.6 | G23: 68.4 | H23: 22.1 | I23: 14.6 | J23: -10.1 | K23: 25.6 | L23: 29.6
A24: Presentation | B24: 75 | C24: 60.7 | D24: 48.1 | E24: 46.3 | F24: 37.4 | G24: 33.8 | H24: 13.1 | I24: 1.4 | J24: 15.5 | K24: 12.5 | L24: -3.6
A25: Design | B25: 150 | C25: 75.6 | D25: 72.6 | E25: 75.9 | F25: 81.1 | G25: 83.6 | H25: 69.4 | I25: 40.4 | J25: -0.9 | K25: 48.9 | L25: 59.4
A26: Accel | B26: 100 | C26: 95.1 | D26: 51.2 | E26: 36.6 | F26: 55.8 | G26: 52.4 | H26: -3.8 | I26: 15.1 | J26: 15 | K26: 25.5 | L26: 41.3
A27: Skid Pad | B27: 75 | C27: 45.9 | D27: 32.7 | E27: 40.1 | F27: 47.1 | G27: 37.2 | H27: 2.6 | I27: 14.5 | J27: 10.4 | K27: 9.4 | L27: 17.8
A28: Autocross | B28: 125 | C28: 77.3 | D28: 74 | E28: 85.7 | F28: 84.1 | G28: 79.9 | H28: 14.9 | I28: 17.1 | J28: -6.5 | K28: 4.9 | L28: 29.5
A29: Endurance | B29: 275 | C29: 63.1 | D29: 103.3 | E29: 120.2 | F29: 84.1 | G29: 84.7 | H29: -47.1 | I29: 123.3 | J29: 66.3 | K29: -63.1 | L29: 101.5
A30: Efficiency | B30: 100 | C30: 93 | D30: 90.6 | E30: 50.3 | F30: 65.9 | G30: 51 | H30: 2 | I30: 0.8 | J30: -16 | K30: DNS | L30: -9.6
A32: Averages cover ranked teams that scored above 0 in the event. In 2022 only a handful of teams have accel, skid pad, autocross and efficiency scores in the source, so those averages are not comparable with later years.

Sheet Leaderboards
A1: ANNUAL LEADERBOARDS | TOP 10 EACH YEAR
A2: [SCHOOL] rows highlighted. 2022-2025: original workbook data. 2026: SAE official results.
A4: 2022 | 43 ranked | E4: 2023 | 61 ranked | I4: 2024 | 70 ranked | M4: 2025 | 78 ranked | Q4: 2026 | 88 ranked
A5: # | B5: Team | C5: Total | E5: # | F5: Team | G5: Total | I5: # | J5: Team | K5: Total | M5: # | N5: Team | O5: Total | Q5: # | R5: Team | S5: Total
A6: 1 | B6: Ecole Polytechnique Montreal | C6: 847 | E6: 1 | F6: Ecole de Technologie Superieure | G6: 919.1 | I6: 1 | J6: Rochester Institute of Technology | K6: 760.6 | M6: 1 | N6: Oregon State Univ | O6: 790.4 | Q6: 1 | R6: Oregon State Univ | S6: 895.5
A7: 2 | B7: Univ of Michigan - Ann Arbor | C7: 837 | E7: 2 | F7: [SCHOOL] | G7: 762.4 | I7: 2 | J7: Ecole Polytechnique Montreal | K7: 757.8 | M7: 2 | N7: San Jose State University | O7: 785.2 | Q7: 2 | R7: Rochester Institute of Technology | S7: 856.7
A8: 3 | B8: Georgia Institute of Technology | C8: 661.3 | E8: 3 | F8: Univ of Washington | G8: 734.4 | I8: 3 | J8: Univ of Wisconsin - Madison | K8: 754.1 | M8: 3 | N8: Georgia Institute of Technology | O8: 772.2 | Q8: 3 | R8: Univ of Pittsburgh - Pittsburgh | S8: 807.2
A9: 4 | B9: Oregon State Univ | C9: 650.4 | E9: 4 | F9: Rochester Institute of Technology | G9: 728.3 | I9: 4 | J9: Georgia Institute of Technology | K9: 751.7 | M9: 4 | N9: Ecole Polytechnique Montreal | O9: 756.1 | Q9: 4 | R9: [SCHOOL] | S9: 756.9
A10: 5 | B10: [SCHOOL] | C10: 646 | E10: 5 | F10: Univ of Toronto | G10: 716.5 | I10: 5 | J10: San Jose State University | K10: 724.3 | M10: 5 | N10: Univ of Washington | O10: 753.5 | Q10: 5 | R10: Univ of Connecticut | S10: 756.8
A11: 6 | B11: Ecole De Technologie Superieure | C11: 423.7 | E11: 6 | F11: Kennesaw State University | G11: 622.4 | I11: 6 | J11: Cornell Univ | K11: 711.9 | M11: 6 | N11: Univ of Pittsburgh - Pittsburgh | O11: 723.4 | Q11: 6 | R11: Univ of Wisconsin - Madison | S11: 743.9
A12: 7 | B12: Univ of Texas - Austin | C12: 384.4 | E12: 7 | F12: Univ of Minnesota - Twin Cities | G12: 611.2 | I12: 7 | J12: Univ of Illinois - Urbana Champaign | K12: 700 | M12: 7 | N12: National Univ of Singapore | O12: 708.6 | Q12: 7 | R12: California Polytechnic State Univ-SLO | S12: 717.5
A13: 8 | B13: San Jose State University | C13: 337.4 | E13: 8 | F13: Virginia Tech | G13: 588.4 | I13: 8 | J13: Univ of Washington | K13: 687.6 | M13: 8 | N13: Rochester Institute of Technology | O13: 701.7 | Q13: 8 | R13: Kookmin Univ | S13: 696
A14: 9 | B14: Univ of Pennsylvania | C14: 276.3 | E14: 9 | F14: Univ of Texas - Arlington | G14: 575.8 | I14: 9 | J14: Univ of Pittsburgh - Pittsburgh | K14: 682.7 | M14: 9 | N14: Massachusetts Inst of Tech | O14: 597.6 | Q14: 9 | R14: Cornell Univ | S14: 681.3
A15: 10 | B15: McGill Univ | C15: 272.3 | E15: 10 | F15: Georgia Institute of Technology | G15: 545.1 | I15: 10 | J15: Univ of Toronto | K15: 682.7 | M15: 10 | N15: Purdue Univ - W Lafayette | O15: 593 | Q15: 10 | R15: Univ of Michigan - Ann Arbor | S15: 671.3
I17: 14 | J17: [SCHOOL] | K17: 589.9 | M17: 13 | N17: [SCHOOL] | O17: 518

Sheet 2026 Results
A1: 2026 MICHIGAN ELECTRIC | FULL OFFICIAL RESULTS
A2: All 88 ranked teams, copied from the SAE official results PDF (printed 6/28/2026). Blank event cell = team did not score in that event. Column O is a live check.
A4: Place | B4: Car # | C4: Team | D4: Total | E4: Cost | F4: Present-ation | G4: Design | H4: Accel | I4: Skid Pad | J4: Auto-cross | K4: Endur-ance | L4: Effi-ciency | M4: Penalty | N4: Event sum + penalty | O4: Diff vs reported
A5: 1 | B5: 1 | C5: Oregon State Univ | D5: 895.5 | E5: 89.1 | F5: 75 | G5: 134 | H5: 81.8 | I5: 67.7 | J5: 124.4 | K5: 275 | L5: 48.6 | N5: =SUM(E5:L5)+N(M5) -> 895.6 | O5: =N5-D5 -> 0.1
A6: 2 | B6: 8 | C6: Rochester Institute of Technology | D6: 856.7 | E6: 78.4 | F6: 73.4 | G6: 141 | H6: 95.1 | I6: 75 | J6: 125 | K6: 216.5 | L6: 52.3 | N6: =SUM(E6:L6)+N(M6) -> 856.7 | O6: =N6-D6 -> 0
A7: 3 | B7: 6 | C7: Univ of Pittsburgh - Pittsburgh | D7: 807.2 | E7: 86.5 | F7: 17.6 | G7: 140 | H7: 83.4 | I7: 56.1 | J7: 117 | K7: 206.5 | L7: 100 | N7: =SUM(E7:L7)+N(M7) -> 807.1 | O7: =N7-D7 -> -0.1
A8: 4 | B8: 46 | C8: [SCHOOL] | D8: 756.9 | E8: 98 | F8: 30.2 | G8: 143 | H8: 93.7 | I8: 55 | J8: 109.4 | K8: 186.2 | L8: 41.4 | N8: =SUM(E8:L8)+N(M8) -> 756.9 | O8: =N8-D8 -> 0
A9: 5 | B9: 103 | C9: Univ of Connecticut | D9: 756.8 | E9: 91.8 | F9: 70.6 | G9: 90 | H9: 52.9 | I9: 65.1 | J9: 118.2 | K9: 202.2 | L9: 66.1 | N9: =SUM(E9:L9)+N(M9) -> 756.9 | O9: =N9-D9 -> 0.1
A10: 6 | B10: 38 | C10: Univ of Wisconsin - Madison | D10: 743.9 | E10: 84.2 | F10: 15 | G10: 150 | H10: 100 | I10: 56.6 | J10: 121.6 | K10: 158.1 | L10: 58.4 | N10: =SUM(E10:L10)+N(M10) -> 743.9 | O10: =N10-D10 -> 0
A11: 7 | B11: 62 | C11: California Polytechnic State Univ-SLO | D11: 717.5 | E11: 84.1 | F11: 37.4 | G11: 120 | H11: 45.8 | I11: 45.5 | J11: 101.6 | K11: 227.3 | L11: 55.8 | N11: =SUM(E11:L11)+N(M11) -> 717.5 | O11: =N11-D11 -> 0
A12: 8 | B12: 30 | C12: Kookmin Univ | D12: 696 | E12: 63.4 | F12: 33.7 | G12: 132 | H12: 47.1 | I12: 52.6 | J12: 106.1 | K12: 218.1 | L12: 43 | N12: =SUM(E12:L12)+N(M12) -> 696 | O12: =N12-D12 -> 0
A13: 9 | B13: 19 | C13: Cornell Univ | D13: 681.3 | E13: 83.1 | F13: 19.1 | G13: 138 | H13: 89.4 | I13: 24.9 | J13: 97.7 | K13: 186.8 | L13: 42.2 | N13: =SUM(E13:L13)+N(M13) -> 681.2 | O13: =N13-D13 -> -0.1
A14: 10 | B14: 65 | C14: Univ of Michigan - Ann Arbor | D14: 671.3 | E14: 85 | F14: 70.7 | G14: 115 | H14: 57.3 | I14: 50.5 | J14: 101.4 | K14: 151.3 | L14: 40.1 | N14: =SUM(E14:L14)+N(M14) -> 671.3 | O14: =N14-D14 -> 0
A15: 11 | B15: 99 | C15: Ecole de Technologie Superieure | D15: 625.8 | E15: 77.8 | F15: 68 | G15: 138 | H15: 98.6 | I15: 56.3 | J15: 115 | K15: 15 | L15: 57.1 | N15: =SUM(E15:L15)+N(M15) -> 625.8 | O15: =N15-D15 -> 0
A16: 12 | B16: 98 | C16: Texas A&M Univ | D16: 609.7 | E16: 62.5 | F16: 19.5 | G16: 115 | H16: 66.9 | I16: 43.9 | J16: 118.8 | K16: 154.9 | L16: 28.2 | N16: =SUM(E16:L16)+N(M16) -> 609.7 | O16: =N16-D16 -> 0
A17: 13 | B17: 14 | C17: Univ of Akron | D17: 576.1 | E17: 68.5 | F17: 30.1 | G17: 90 | H17: 93.8 | I17: 42.1 | J17: 49.3 | K17: 202.3 | N17: =SUM(E17:L17)+N(M17) -> 576.1 | O17: =N17-D17 -> 0
A18: 14 | B18: 5 | C18: Univ of Washington | D18: 562.4 | E18: 89.8 | F18: 52.6 | G18: 146 | H18: 90.8 | I18: 69.4 | J18: 107.8 | K18: 6 | N18: =SUM(E18:L18)+N(M18) -> 562.4 | O18: =N18-D18 -> 0
A19: 15 | B19: 70 | C19: Univ of Pennsylvania | D19: 543 | E19: 89.7 | F19: 75 | G19: 139 | H19: 61 | I19: 36.5 | J19: 0 | K19: 104.1 | L19: 37.6 | N19: =SUM(E19:L19)+N(M19) -> 542.9 | O19: =N19-D19 -> -0.1
A20: 16 | B20: 111 | C20: Auburn Univ | D20: 527.8 | E20: 46.6 | F20: 15.5 | G20: 100 | H20: 79.1 | I20: 51.6 | J20: 94.2 | K20: 112.1 | L20: 28.7 | N20: =SUM(E20:L20)+N(M20) -> 527.8 | O20: =N20-D20 -> 0
A21: 17 | B21: 26 | C21: Western Washington Univ | D21: 508.5 | E21: 90.2 | F21: 18.8 | G21: 65 | H21: 31.4 | I21: 24 | J21: 78.2 | K21: 129.2 | L21: 71.7 | N21: =SUM(E21:L21)+N(M21) -> 508.5 | O21: =N21-D21 -> 0
A22: 18 | B22: 21 | C22: Univ of Kansas - Lawrence | D22: 491.6 | E22: 69.7 | F22: 16.5 | G22: 65 | H22: 55.6 | I22: 51.8 | J22: 102.2 | K22: 81.5 | L22: 49.3 | N22: =SUM(E22:L22)+N(M22) -> 491.6 | O22: =N22-D22 -> 0
A23: 19 | B23: 43 | C23: Concordia University | D23: 475.1 | E23: 94.6 | F23: 48.1 | G23: 95 | H23: 47.8 | I23: 45.8 | J23: 81.8 | K23: 24 | L23: 38 | N23: =SUM(E23:L23)+N(M23) -> 475.1 | O23: =N23-D23 -> 0
A24: 20 | B24: 9 | C24: Massachusetts Inst of Tech | D24: 462 | E24: 52.3 | F24: 68.5 | G24: 105 | H24: 75.1 | I24: 51.1 | J24: 99.9 | K24: 10 | N24: =SUM(E24:L24)+N(M24) -> 461.9 | O24: =N24-D24 -> -0.1
A25: 21 | B25: 86 | C25: Rensselaer Polytechnic Inst | D25: 429.4 | E25: 67.5 | F25: 49.3 | G25: 65 | H25: 4.5 | I25: 21.8 | J25: 64.7 | K25: 67.4 | L25: 89.2 | N25: =SUM(E25:L25)+N(M25) -> 429.4 | O25: =N25-D25 -> 0
A26: 22 | B26: 112 | C26: Northwestern Univ | D26: 394.3 | E26: 85.2 | F26: 62 | G26: 95 | J26: 6.5 | K26: 111.1 | L26: 34.4 | N26: =SUM(E26:L26)+N(M26) -> 394.2 | O26: =N26-D26 -> -0.1
A27: 23 | B27: 2 | C27: San Jose State University | D27: 391.5 | E27: 81.3 | F27: 20 | G27: 115 | I27: 50.9 | J27: 117.4 | K27: 7 | N27: =SUM(E27:L27)+N(M27) -> 391.6 | O27: =N27-D27 -> 0.1
A28: 24 | B28: 93 | C28: Univ of Calgary | D28: 370.7 | E28: 63.6 | F28: 37.4 | G28: 100 | H28: 50.4 | I28: 24.2 | J28: 70.2 | K28: 25 | N28: =SUM(E28:L28)+N(M28) -> 370.8 | O28: =N28-D28 -> 0.1
A29: 25 | B29: 79 | C29: Univ of Maryland - College Park | D29: 364.8 | E29: 69.5 | F29: 18.8 | G29: 100 | H29: 66.5 | I29: 29.6 | J29: 74.4 | K29: 6 | N29: =SUM(E29:L29)+N(M29) -> 364.8 | O29: =N29-D29 -> 0
A30: 26 | B30: 66 | C30: Univ of Calif - Los Angeles | D30: 358.5 | E30: 77.1 | F30: 46.3 | G30: 105 | H30: 4.5 | I30: 35.3 | J30: 65.3 | K30: 25 | N30: =SUM(E30:L30)+N(M30) -> 358.5 | O30: =N30-D30 -> 0
A31: 27 | B31: 35 | C31: Univ of North Carolina - Charlotte | D31: 324 | E31: 69.5 | F31: 56.6 | G31: 80 | H31: 24.8 | I31: 31.1 | J31: 37.9 | K31: 24 | N31: =SUM(E31:L31)+N(M31) -> 323.9 | O31: =N31-D31 -> -0.1
A32: 28 | B32: 87 | C32: Univ of Florida | D32: 304 | E32: 56.7 | F32: 55.3 | G32: 120 | I32: 23.6 | J32: 42.5 | K32: 6 | N32: =SUM(E32:L32)+N(M32) -> 304.1 | O32: =N32-D32 -> 0.1
A33: 29 | B33: 108 | C33: Univ of New Mexico | D33: 288.4 | E33: 74.1 | F33: 58.6 | G33: 70 | H33: 50.7 | I33: 3.5 | J33: 6.5 | K33: 25 | N33: =SUM(E33:L33)+N(M33) -> 288.4 | O33: =N33-D33 -> 0
A34: 30 | B34: 104 | C34: Univ of Calif - Santa Barbara | D34: 281.9 | E34: 72 | F34: 33.5 | G34: 55 | H34: 39.5 | I34: 5.4 | J34: 51.5 | K34: 25 | N34: =SUM(E34:L34)+N(M34) -> 281.9 | O34: =N34-D34 -> 0
A35: 31 | B35: 3 | C35: Georgia Institute of Technology | D35: 274.5 | E35: 94.8 | F35: 59.7 | G35: 120 | N35: =SUM(E35:L35)+N(M35) -> 274.5 | O35: =N35-D35 -> 0
A36: 32 | B36: 56 | C36: Louisiana State Univ | D36: 274.2 | E36: 79.4 | F36: 45.5 | G36: 50 | H36: 25.4 | I36: 20.2 | J36: 36.7 | K36: 17 | N36: =SUM(E36:L36)+N(M36) -> 274.2 | O36: =N36-D36 -> 0
A37: 33 | B37: 4 | C37: Ecole Polytechnique Montreal | D37: 273.1 | E37: 80.7 | F37: 57.4 | G37: 135 | N37: =SUM(E37:L37)+N(M37) -> 273.1 | O37: =N37-D37 -> 0
A38: 34 | B38: 113 | C38: Kennesaw State University | D38: 258.2 | E38: 91.5 | F38: 19.4 | G38: 85 | H38: 0 | I38: 37.4 | J38: 0 | K38: 25 | N38: =SUM(E38:L38)+N(M38) -> 258.3 | O38: =N38-D38 -> 0.1
A39: 35 | B39: 97 | C39: Univ of Texas - Austin | D39: 251 | E39: 89.9 | F39: 56.1 | G39: 105 | N39: =SUM(E39:L39)+N(M39) -> 251 | O39: =N39-D39 -> 0
A40: 36 | B40: 92 | C40: Univ of Illinois - Urbana Champaign | D40: 246.1 | E40: 85.2 | F40: 16.9 | G40: 144 | N40: =SUM(E40:L40)+N(M40) -> 246.1 | O40: =N40-D40 -> 0
A41: 37 | B41: 51 | C41: Univ of Southern California | D41: 244.7 | E41: 51.2 | F41: 18.8 | G41: 70 | H41: 4.5 | I41: 39.6 | J41: 60.7 | N41: =SUM(E41:L41)+N(M41) -> 244.8 | O41: =N41-D41 -> 0.1
...

Sheet Competitors
A1: COMPETITOR TRACKER | RANK AND SCORE, 2022-2026
A2: Teams that finished in the top 10 in two or more years, plus [SCHOOL]. Blank = not ranked / no result that year.
A4: TRACKER
A5: Team | B5: 2022 place | C5: 2022 pts | D5: 2023 place | E5: 2023 pts | F5: 2024 place | G5: 2024 pts | H5: 2025 place | I5: 2025 pts | J5: 2026 place | K5: 2026 pts | L5: Change 2025 to 2026 (pts) | M5: 2026 vs [SCHOOL] (pts) | N5: Trend
A6: [SCHOOL] | B6: 5 | C6: 646 | D6: 2 | E6: 762.4 | F6: 14 | G6: 589.9 | H6: 13 | I6: 518 | J6: 4 | K6: 756.9 | L6: =IF(AND(ISNUMBER(I6),ISNUMBER(K6)),K6-I6,"") -> 238.9 | M6: =IF(ISNUMBER(K6),K6-$K$6,"") -> 0 | N6: =IF(L6="","",IF(L6>10,"up",IF(L6<-10,"down","flat"))) -> up
A7: Oregon State Univ | B7: 4 | C7: 650.4 | D7: 15 | E7: 362.8 | F7: 21 | G7: 450.7 | H7: 1 | I7: 790.4 | J7: 1 | K7: 895.5 | L7: =IF(AND(ISNUMBER(I7),ISNUMBER(K7)),K7-I7,"") -> 105.1 | M7: =IF(ISNUMBER(K7),K7-$K$6,"") -> 138.6 | N7: =IF(L7="","",IF(L7>10,"up",IF(L7<-10,"down","flat"))) -> up
A8: Rochester Institute of Technology | D8: 4 | E8: 728.3 | F8: 1 | G8: 760.6 | H8: 8 | I8: 701.7 | J8: 2 | K8: 856.7 | L8: =IF(AND(ISNUMBER(I8),ISNUMBER(K8)),K8-I8,"") -> 155 | M8: =IF(ISNUMBER(K8),K8-$K$6,"") -> 99.8 | N8: =IF(L8="","",IF(L8>10,"up",IF(L8<-10,"down","flat"))) -> up
A9: Univ of Pittsburgh - Pittsburgh | F9: 9 | G9: 682.7 | H9: 6 | I9: 723.4 | J9: 3 | K9: 807.2 | L9: =IF(AND(ISNUMBER(I9),ISNUMBER(K9)),K9-I9,"") -> 83.8 | M9: =IF(ISNUMBER(K9),K9-$K$6,"") -> 50.3 | N9: =IF(L9="","",IF(L9>10,"up",IF(L9<-10,"down","flat"))) -> up
A10: Univ of Wisconsin - Madison | B10: 12 | C10: 250.6 | D10: 13 | E10: 420.1 | F10: 3 | G10: 754.1 | H10: 12 | I10: 566.6 | J10: 6 | K10: 743.9 | L10: =IF(AND(ISNUMBER(I10),ISNUMBER(K10)),K10-I10,"") -> 177.3 | M10: =IF(ISNUMBER(K10),K10-$K$6,"") -> -13 | N10: =IF(L10="","",IF(L10>10,"up",IF(L10<-10,"down","flat"))) -> up
A11: Cornell Univ | B11: 18 | C11: 199.9 | D11: 12 | E11: 491.8 | F11: 6 | G11: 711.9 | H11: 22 | I11: 338 | J11: 9 | K11: 681.3 | L11: =IF(AND(ISNUMBER(I11),ISNUMBER(K11)),K11-I11,"") -> 343.3 | M11: =IF(ISNUMBER(K11),K11-$K$6,"") -> -75.6 | N11: =IF(L11="","",IF(L11>10,"up",IF(L11<-10,"down","flat"))) -> up
A12: Univ of Michigan - Ann Arbor | B12: 2 | C12: 837 | D12: 22 | E12: 275.2 | F12: 18 | G12: 520.7 | H12: 20 | I12: 390.6 | J12: 10 | K12: 671.3 | L12: =IF(AND(ISNUMBER(I12),ISNUMBER(K12)),K12-I12,"") -> 280.7 | M12: =IF(ISNUMBER(K12),K12-$K$6,"") -> -85.6 | N12: =IF(L12="","",IF(L12>10,"up",IF(L12<-10,"down","flat"))) -> up
A13: Ecole de Technologie Superieure | B13: 6 | C13: 423.7 | D13: 1 | E13: 919.1 | F13: 16 | G13: 524.6 | H13: 44 | I13: 181.9 | J13: 11 | K13: 625.8 | L13: =IF(AND(ISNUMBER(I13),ISNUMBER(K13)),K13-I13,"") -> 443.9 | M13: =IF(ISNUMBER(K13),K13-$K$6,"") -> -131.1 | N13: =IF(L13="","",IF(L13>10,"up",IF(L13<-10,"down","flat"))) -> up
A14: Univ of Washington | B14: 13 | C14: 249.4 | D14: 3 | E14: 734.4 | F14: 8 | G14: 687.6 | H14: 5 | I14: 753.5 | J14: 14 | K14: 562.4 | L14: =IF(AND(ISNUMBER(I14),ISNUMBER(K14)),K14-I14,"") -> -191.1 | M14: =IF(ISNUMBER(K14),K14-$K$6,"") -> -194.5 | N14: =IF(L14="","",IF(L14>10,"up",IF(L14<-10,"down","flat"))) -> down
A15: San Jose State University | B15: 8 | C15: 337.4 | D15: 23 | E15: 254.8 | F15: 5 | G15: 724.3 | H15: 2 | I15: 785.2 | J15: 23 | K15: 391.5 | L15: =IF(AND(ISNUMBER(I15),ISNUMBER(K15)),K15-I15,"") -> -393.7 | M15: =IF(ISNUMBER(K15),K15-$K$6,"") -> -365.4 | N15: =IF(L15="","",IF(L15>10,"up",IF(L15<-10,"down","flat"))) -> down
A16: Georgia Institute of Technology | B16: 3 | C16: 661.3 | D16: 10 | E16: 545.1 | F16: 4 | G16: 751.7 | H16: 3 | I16: 772.2 | J16: 31 | K16: 274.5 | L16: =IF(AND(ISNUMBER(I16),ISNUMBER(K16)),K16-I16,"") -> -497.7 | M16: =IF(ISNUMBER(K16),K16-$K$6,"") -> -482.4 | N16: =IF(L16="","",IF(L16>10,"up",IF(L16<-10,"down","flat"))) -> down
A17: Ecole Polytechnique Montreal | B17: 1 | C17: 847 | D17: 11 | E17: 494.7 | F17: 2 | G17: 757.8 | H17: 4 | I17: 756.1 | J17: 33 | K17: 273.1 | L17: =IF(AND(ISNUMBER(I17),ISNUMBER(K17)),K17-I17,"") -> -483 | M17: =IF(ISNUMBER(K17),K17-$K$6,"") -> -483.8 | N17: =IF(L17="","",IF(L17>10,"up",IF(L17<-10,"down","flat"))) -> down
A18: Univ of Toronto | B18: 21 | C18: 181.7 | D18: 5 | E18: 716.5 | F18: 10 | G18: 682.7 | H18: 15 | I18: 490.8 | J18: 51 | K18: 211.1 | L18: =IF(AND(ISNUMBER(I18),ISNUMBER(K18)),K18-I18,"") -> -279.7 | M18: =IF(ISNUMBER(K18),K18-$K$6,"") -> -545.8 | N18: =IF(L18="","",IF(L18>10,"up",IF(L18<-10,"down","flat"))) -> down
A20: BIGGEST MOVERS 2025 TO 2026 (teams ranked in both years)
A21: Team | B21: 2025 pts | C21: 2026 pts | D21: Change
A22: Ecole de Technologie Superieure | B22: 181.9 | C22: 625.8 | D22: 443.9
A23: Univ of Akron | B23: 154.4 | C23: 576.1 | D23: 421.7
A24: Univ of Kansas - Lawrence | B24: 95.9 | C24: 491.6 | D24: 395.7
A25: Texas A&M Univ | B25: 235.3 | C25: 609.7 | D25: 374.4
A26: Cornell Univ | B26: 338 | C26: 681.3 | D26: 343.3
A27: Concordia University | B27: 194.4 | C27: 475.1 | D27: 280.7
A28: Univ of Michigan - Ann Arbor | B28: 390.6 | C28: 671.3 | D28: 280.7
A29: Auburn Univ | B29: 252.4 | C29: 527.8 | D29: 275.4
A30: San Jose State University | B30: 785.2 | C30: 391.5 | D30: -393.7
A31: Purdue Univ - W Lafayette | B31: 593 | C31: 192.3 | D31: -400.7
A32: National Univ of Singapore | B32: 708.6 | C32: 235 | D32: -473.6
A33: Ecole Polytechnique Montreal | B33: 756.1 | C33: 273.1 | D33: -483
A34: Georgia Institute of Technology | B34: 772.2 | C34: 274.5 | D34: -497.7
A35: [SCHOOL] gained 238.9 pts from 2025 to 2026, the 12th-biggest gain among the 69 teams ranked in both years.

Sheet Car Specs Analysis
A1: CAR SPECS ANALYSIS | DO WEIGHT, VOLTAGE AND MOTORS MATTER?
A2: Ranked teams with reported specs, 2023-2026. Descriptive only: teams that score well differ in many ways, so these are patterns, not proof of cause. Weight excludes 3 teams in 2026 whose weight is without battery pack.
A4: CORRELATION WITH TOTAL SCORE (Pearson r; teams with spec data)
A5: Spec | B5: 2023 | C5: 2024 | D5: 2025 | E5: 2026 | F5: All 4 years | G5: Teams (all)
A6: Weight (kg) | B6: -0.15 | C6: -0.39 | D6: -0.45 | E6: -0.15 | F6: -0.26 | G6: 285
A7: Voltage (V) | B7: 0.26 | C7: -0.04 | D7: -0.03 | E7: 0.29 | F7: 0.14 | G7: 287
A8: Motors | B8: 0.47 | C8: 0.36 | D8: 0.31 | E8: 0.5 | F8: 0.41 | G8: 288
A9: r near 0 means no clear linear link; negative means heavier / higher values go with lower scores. A few teams have no score data for every event, so total score also reflects whether a team finished the dynamic events.
A11: MOTORS | average total score by number of motors
A12: Motors | B12: 2023 avg | C12: 2024 avg | D12: 2025 avg | E12: 2026 avg | F12: All years avg | G12: Teams (all) | H12: Best total
A13: 1 motor | B13: 239.4 | C13: 307.5 | D13: 251.6 | E13: 238.8 | F13: 258.6 | G13: 213 | H13: 785.2
A14: 2 motors | B14: 201.6 | C14: 198.2 | D14: 312.2 | F14: 234.2 | G14: 15 | H14: 593
A15: 3 motors | F15: 267.2 | G15: 2 | H15: 394.3
A16: 4 motors | B16: 508.7 | C16: 536.7 | D16: 424.2 | E16: 484.9 | F16: 483.2 | G16: 58 | H16: 919.1
A17: Cells are blank when fewer than 3 teams had that setup. 3-motor and 2-motor counts are small.
A19: WEIGHT | average total score by weight bracket
A20: Weight bracket | B20: 2023 avg | C20: 2024 avg | D20: 2025 avg | E20: 2026 avg | F20: All years avg | G20: Teams (all) | H20: Best total
A21: under 190 kg | B21: 281.8 | C21: 363.9 | D21: 290.1 | E21: 360.8 | F21: 334.5 | G21: 31 | H21: 919.1
A22: 190-199.9 | B22: 291.5 | C22: 414.4 | D22: 481.4 | E22: 297.9 | F22: 341.8 | G22: 33 | H22: 772.2
A23: 200-209.9 | B23: 411.4 | C23: 573.2 | D23: 499.4 | E23: 318.6 | F23: 418.3 | G23: 51 | H23: 895.5
A24: 210-219.9 | B24: 445.7 | C24: 343.3 | D24: 303.1 | E24: 292.6 | F24: 325.2 | G24: 47 | H24: 762.4
A25: 220-239.9 | B25: 199.8 | C25: 229.7 | D25: 255.9 | E25: 333.7 | F25: 251.2 | G25: 65 | H25: 790.4
A26: 240 kg and over | B26: 217.9 | C26: 256.2 | D26: 174.9 | E26: 168.7 | F26: 215 | G26: 58 | H26: 716.5
A28: VOLTAGE | average total score by tractive voltage bracket
A29: Voltage bracket | B29: 2023 avg | C29: 2024 avg | D29: 2025 avg | E29: 2026 avg | F29: All years avg | G29: Teams (all) | H29: Best total
A30: under 400 V | B30: 266.6 | C30: 377.4 | D30: 318.2 | E30: 208 | F30: 294.4 | G30: 93 | H30: 790.4
A31: 400-499 V | B31: 214.6 | C31: 312.8 | D31: 263.5 | E31: 275.4 | F31: 269.3 | G31: 89 | H31: 807.2
A32: 500-599 V | B32: 373 | C32: 300.5 | D32: 259 | E32: 342.8 | F32: 317.4 | G32: 70 | H32: 895.5
A33: 600 V and over | B33: 385.7 | C33: 405.5 | D33: 305.4 | E33: 387 | F33: 382.1 | G33: 35 | H33: 919.1
A35: [SCHOOL] CAR SPECS BY YEAR
A36: Year | B36: Motors | C36: Voltage (V) | D36: Weight (kg) | E36: Weight rank (1 = lightest) | F36: Of teams with weight | G36: Place | H36: Total
A37: 2023 | B37: 4 | C37: 600 | D37: 218.2 | E37: 28 | F37: 61 | G37: 2 | H37: 762.4
A38: 2024 | B38: 4 | C38: 600 | D38: 264 | E38: 60 | F38: 66 | G38: 14 | H38: 589.9
A39: 2025 | B39: 4 | C39: 350 | D39: 210 | E39: 18 | F39: 74 | G39: 13 | H39: 518
A40: 2026 | B40: 4 | C40: 600 | D40: 191.4 | E40: 16 | F40: 84 | G40: 4 | H40: 756.9
A41: [SCHOOL] 2022 specs are not in the source data. 2023-2025 specs come from the original workbook (not independently re-verified). 2026 specs come from the SAE team information pages ("For Information Only, Not Validated").

Sheet Car Specs Data
A1: CAR SPECS DATA | ranked teams with spec data, 2023-2026
A2: Motors, tractive voltage and vehicle weight as reported by teams to SAE. SAE marks the 2026 team information "For Information Only, Not Validated". 2022 has specs for only 5 teams, so it is left out.
A4: Year | B4: Team | C4: Car # | D4: Motors | E4: Voltage (V) | F4: Weight (kg) | G4: Place | H4: Total | I4: Weight basis | J4: Note
A5: 2023 | B5: Ecole de Technologie Superieure | C5: 233 | D5: 4 | E5: 600 | F5: 179.2 | G5: 1 | H5: 919.1 | I5: Reported
A6: 2023 | B6: [SCHOOL] | C6: 283 | D6: 4 | E6: 600 | F6: 218.2 | G6: 2 | H6: 762.4 | I6: Reported | J6: [SCHOOL]
A7: 2023 | B7: Univ of Washington | C7: 267 | D7: 4 | E7: 550 | F7: 215 | G7: 3 | H7: 734.4 | I7: Reported
A8: 2023 | B8: Rochester Institute of Technology | C8: 266 | D8: 1 | E8: 380 | F8: 202.3 | G8: 4 | H8: 728.3 | I8: Reported
A9: 2023 | B9: Univ of Toronto | C9: 217 | D9: 1 | E9: 525 | F9: 259 | G9: 5 | H9: 716.5 | I9: Reported
A10: 2023 | B10: Kennesaw State University | C10: 234 | D10: 1 | E10: 300 | F10: 206.4 | G10: 6 | H10: 622.4 | I10: Reported
A11: 2023 | B11: Univ of Minnesota - Twin Cities | C11: 288 | D11: 1 | E11: 350 | F11: 203.2 | G11: 7 | H11: 611.2 | I11: Reported
A12: 2023 | B12: Virginia Tech | C12: 256 | D12: 1 | E12: 350 | F12: 237.7 | G12: 8 | H12: 588.4 | I12: Reported
A13: 2023 | B13: Univ of Texas - Arlington | C13: 274 | D13: 1 | E13: 500 | F13: 197.8 | G13: 9 | H13: 575.8 | I13: Reported
A14: 2023 | B14: Georgia Institute of Technology | C14: 277 | D14: 4 | E14: 530 | F14: 198.7 | G14: 10 | H14: 545.1 | I14: Reported
A15: 2023 | B15: Ecole Polytechnique Montreal | C15: 212 | D15: 1 | E15: 400 | F15: 202.8 | G15: 11 | H15: 494.7 | I15: Reported
A16: 2023 | B16: Cornell Univ | C16: 287 | D16: 1 | E16: 336 | F16: 218.2 | G16: 12 | H16: 491.8 | I16: Reported
A17: 2023 | B17: Univ of Wisconsin - Madison | C17: 270 | D17: 4 | E17: 320 | F17: 243.1 | G17: 13 | H17: 420.1 | I17: Reported
A18: 2023 | B18: Universite Laval | C18: 268 | D18: 4 | E18: 420 | F18: 196.9 | G18: 14 | H18: 408.4 | I18: Reported
... A78: 2024 | B78: Virginia Tech | C78: 208 | D78: 1 | E78: 300 | F78: 201.4 | G78: 13 | H78: 627.9 | I78: Reported
A79: 2024 | B79: [SCHOOL] | C79: 202 | D79: 4 | E79: 600 | F79: 264 | G79: 14 | H79: 589.9 | I79: Reported | J79: [SCHOOL]
A80: 2024 | B80: Kennesaw State University | C80: 206 | D80: 1 | E80: 300 | F80: 202.8 | G80: 15 | H80: 568.7 | I80: Reported
A81: 2024 | B81: Ecole De Technologie Superieure | C81: 201 | D81: 4 | E81: 600 | F81: 181 | G81: 16 | H81: 524.6 | I81: Reported
A82: 2024 | B82: Univ of Akron | C82: 288 | D82: 1 | E82: 375 | F82: 185.1 | G82: 17 | H82: 524.1 | I82: Reported
A83: 2024 | B83: Univ of Michigan - Ann Arbor | C83: 250 | D83: 4 | E83: 600 | F83: 193.2 | G83: 18 | H83: 520.7 | I83: Reported
A84: 2024 | B84: Concordia University | C84: 228 | D84: 1 | E84: 350 | F84: 230 | G84: 19 | H84: 496.6 | I84: Reported
A85: 2024 | B85: Western University | C85: 283 | D85: 1 | E85: 420 | F85: 216.4 | G85: 20 | H85: 470.6 | I85: Reported
A86: 2024 | B86: Oregon State Univ | C86: 247 | D86: 4 | E86: 600 | F86: 202.8 | G86: 21 | H86: 450.7 | I86: Reported
A87: 2024 | B87: Univ of Calif - Davis | C87: 290 | D87: 1 | E87: 500 | F87: 220 | G87: 22 | H87: 391.3 | I87: Reported
A88: 2024 | B88: Université Laval | C88: 245 | D88: 4 | E88: 420 | F88: 198.2 | G88: 23 | H88: 391 | I88: Reported
A89: 2024 | B89: Massachusetts Inst of Tech | C89: 246 | D89: 1 | E89: 400 | F89: 264.9 | G89: 24 | H89: 373.3 | I89: Reported
A90: 2024 | B90: Penn State Univ - University Park | C90: 285 | D90: 1 | E90: 375 | F90: 249.9 | G90: 25 | H90: 363.4 | I90: Reported
A91: 2024 | B91: Univ of Texas - Arlington | C91: 209 | D91: 1 | E91: 500 | F91: 224.1 | G91: 26 | H91: 356.1 | I91: Reported
... A143: 2025 | B143: Univ of Wisconsin - Madison | C143: 203 | D143: 2 | E143: 300 | F143: 167.4 | G143: 12 | H143: 566.6 | I143: Reported
A144: 2025 | B144: [SCHOOL] | C144: 299 | D144: 4 | E144: 350 | F144: 210 | G144: 13 | H144: 518 | I144: Reported | J144: [SCHOOL]
A145: 2025 | B145: Univ of Connecticut | C145: 301 | D145: 1 | E145: 470 | F145: 220 | G145: 14 | H145: 507.4 | I145: Reported
A146: 2025 | B146: Univ of Toronto | C146: 210 | D146: 1 | E146: 600 | F146: 252.7 | G146: 15 | H146: 490.8 | I146: Reported
A147: 2025 | B147: Univ of Cincinnati | C147: 222 | D147: 1 | E147: 420 | F147: 201.8 | G147: 16 | H147: 483.4 | I147: Reported
A148: 2025 | B148: Kookmin Univ | C148: 248 | D148: 1 | E148: 330 | F148: 239.5 | G148: 17 | H148: 460.2 | I148: Reported
A149: 2025 | B149: Univ of Calif - Santa Cruz | C149: 216 | D149: 1 | E149: 108 | F149: 221.4 | G149: 18 | H149: 443.5 | I149: Reported
A150: 2025 | B150: Université Laval | C150: 268 | D150: 4 | E150: 400 | F150: 192.8 | G150: 19 | H150: 423 | I150: Reported
A151: 2025 | B151: Univ of Michigan - Ann Arbor | C151: 274 | D151: 4 | E151: 600 | F151: 219.5 | G151: 20 | H151: 390.6 | I151: Reported
...

Sheet Formula Hybrid
A1: FORMULA HYBRID + ELECTRIC | ELECTRIC CLASS
A2: A separate competition with its own scoring. Do not compare its points with FSAE Michigan.
A4: 2026 ELECTRIC CLASS PODIUM (organizer results, confirmed on the Dartmouth recap)
A5: Team | B5: Class finish | C5: Acceleration | D5: Autocross | E5: Endurance
A6: [SCHOOL] | B6: 1st | C6: 1st | D6: 2nd | E6: 1st
A7: University of Akron | B7: 2nd | C7: 2nd | D7: 1st | E7: 3rd
A8: University of Calgary | B8: 3rd | C8: 3rd | D8: 3rd | E8: 2nd
A10: [SCHOOL] HISTORY (as listed on the [SCHOOL] team site)
A11: Year | B11: Overall (electric) | C11: Acceleration | D11: Autocross | E11: Design | F11: Endurance | G11: Project mgmt
A12: 2022 | B12: 1st | G12: 1st
A13: 2023 | B13: 2nd | C13: 1st (record) | D13: 1st | E13: 1st | F13: 4th | G13: 3rd
A14: 2024 | B14: 2nd | C14: 1st | D14: 1st | E14: 2nd | F14: 4th | G14: 1st
A15: 2025 | B15: not listed | C15: 1st | D15: 3rd | E15: 2nd | F15: 8th | G15: 1st
A16: 2026 | B16: 1st | C16: 1st | D16: 2nd | E16: 2nd | F16: 1st | G16: 1st per [SCHOOL] site*
A18: *The organizer awards list (formula-hybrid.org announcements) shows MIT as 1st in the 2026 Project Management event, Northeastern 2nd and Akron 3rd, while the [SCHOOL] site lists [SCHOOL] 1st. This is unresolved; treat the 2026 project management placing as unverified. [SCHOOL] also received the IEEE Excellence in EV Engineering award. 2026 organizer event podiums confirm [SCHOOL] 1st in acceleration and endurance, 2nd in autocross and design. Formula Hybrid 2022 details beyond overall and project management were not listed on the [SCHOOL] site.

Sheet Results Data
A1: RESULTS DATA | FSAE ELECTRIC (MICHIGAN) 2022-2026
A2: Every team-year row used in this workbook. 2022-2025 as supplied in the original workbook. 2026 copied from the official SAE results PDF. Columns Q and R are live formulas.
A3: Year | B3: Place | C3: Team | D3: Status | E3: Total | F3: Cost | G3: Present-ation | H3: Design | I3: Accel | J3: Skid Pad | K3: Auto-cross | L3: Endur-ance | M3: Effi-ciency | N3: Penalty | O3: Car # | P3: Ranked? (1/0) | Q3: Event sum + penalty | R3: Diff vs reported | S3: [SCHOOL]? (1/0) | T3: Source
A4: 2022 | B4: 1 | C4: Ecole Polytechnique Montreal | D4: Ranked | E4: 847 | F4: 65.28 | G4: 58.2 | H4: 100 | I4: 98.18 | J4: 51.57 | K4: 109.17 | L4: 275 | M4: 89.6 | P4: 1 | Q4: =IF(P4=1,SUM(F4:M4)+N4,"") -> 847 | R4: =IF(AND(P4=1,ISNUMBER(E4)),Q4-E4,"") -> 0 | S4: 0 | T4: Original uploaded workbook
A5: 2022 | B5: 2 | C5: Univ of Michigan - Ann Arbor | D5: Ranked | E5: 837 | F5: 84.45 | G5: 64 | H5: 140 | I5: 88.57 | J5: 75 | K5: 98.58 | L5: 197.4 | M5: 89.1 | P5: 1 | Q5: =IF(P5=1,SUM(F5:M5)+N5,"") -> 837.1 | R5: =IF(AND(P5=1,ISNUMBER(E5)),Q5-E5,"") -> 0.1 | S5: 0 | T5: Original uploaded workbook
A6: 2022 | B6: 3 | C6: Georgia Institute of Technology | D6: Ranked | E6: 661.3 | F6: 89.1 | G6: 71.2 | H6: 125 | I6: 97.53 | J6: 67.21 | K6: 97.83 | L6: 21 | M6: 92.3 | P6: 1 | Q6: =IF(P6=1,SUM(F6:M6)+N6,"") -> 661.17 | R6: =IF(AND(P6=1,ISNUMBER(E6)),Q6-E6,"") -> -0.13 | S6: 0 | T6: Original uploaded workbook
A7: 2022 | B7: 4 | C7: Oregon State Univ | D7: Ranked | E7: 650.4 | F7: 72.7 | G7: 62 | H7: 100 | I7: 100 | J7: 72.89 | K7: 125 | L7: 31 | M7: 86.7 | P7: 1 | Q7: =IF(P7=1,SUM(F7:M7)+N7,"") -> 650.29 | R7: =IF(AND(P7=1,ISNUMBER(E7)),Q7-E7,"") -> -0.11 | S7: 0 | T7: Original uploaded workbook
A8: 2022 | B8: 5 | C8: [SCHOOL] | D8: Ranked | E8: 646 | F8: 84.21 | G8: 73.8 | H8: 145 | I8: 91.35 | J8: 48.48 | K8: 92.17 | L8: 16 | M8: 95 | P8: 1 | Q8: =IF(P8=1,SUM(F8:M8)+N8,"") -> 646.01 | R8: =IF(AND(P8=1,ISNUMBER(E8)),Q8-E8,"") -> 0.01 | S8: 1 | T8: Original uploaded workbook
A9: 2022 | B9: 6 | C9: Ecole De Technologie Superieure | D9: Ranked | E9: 423.7 | F9: 79.25 | G9: 63.7 | H9: 150 | J9: 45.41 | K9: 82.33 | L9: 3 | P9: 1 | Q9: =IF(P9=1,SUM(F9:M9)+N9,"") -> 423.69 | R9: =IF(AND(P9=1,ISNUMBER(E9)),Q9-E9,"") -> -0.01 | S9: 0 | T9: Original uploaded workbook
A10: 2022 | B10: 7 | C10: Univ of Texas - Austin | D10: Ranked | E10: 384.4 | F10: 59.36 | G10: 62.7 | H10: 80 | L10: 82.3 | M10: 100 | P10: 1 | Q10: =IF(P10=1,SUM(F10:M10)+N10,"") -> 384.36 | R10: =IF(AND(P10=1,ISNUMBER(E10)),Q10-E10,"") -> -0.04 | S10: 0 | T10: Original uploaded workbook
A11: 2022 | B11: 8 | C11: San Jose State University | D11: Ranked | E11: 337.4 | F11: 59.41 | G11: 54.1 | H11: 90 | L11: 35 | M11: 98.6 | P11: 1 | Q11: =IF(P11=1,SUM(F11:M11)+N11,"") -> 337.11 | R11: =IF(AND(P11=1,ISNUMBER(E11)),Q11-E11,"") -> -0.29 | S11: 0 | T11: Original uploaded workbook
A12: 2022 | B12: 9 | C12: Univ of Pennsylvania | D12: Ranked | E12: 276.3 | F12: 78.78 | G12: 72.5 | H12: 125 | P12: 1 | Q12: =IF(P12=1,SUM(F12:M12)+N12,"") -> 276.28 | R12: =IF(AND(P12=1,ISNUMBER(E12)),Q12-E12,"") -> -0.02 | S12: 0 | T12: Original uploaded workbook
A13: 2022 | B13: 10 | C13: McGill Univ | D13: Ranked | E13: 272.3 | F13: 90.9 | G13: 71.4 | H13: 110 | P13: 1 | Q13: =IF(P13=1,SUM(F13:M13)+N13,"") -> 272.3 | R13: =IF(AND(P13=1,ISNUMBER(E13)),Q13-E13,"") -> 0 | S13: 0 | T13: Original uploaded workbook
A14: 2022 | B14: 11 | C14: California Polytechnic State Univ-SLO | D14: Ranked | E14: 257.7 | F14: 88.7 | G14: 59 | H14: 110 | P14: 1 | Q14: =IF(P14=1,SUM(F14:M14)+N14,"") -> 257.7 | R14: =IF(AND(P14=1,ISNUMBER(E14)),Q14-E14,"") -> 0 | S14: 0 | T14: Original uploaded workbook
A15: 2022 | B15: 12 | C15: Univ of Wisconsin - Madison | D15: Ranked | E15: 250.6 | F15: 82 | G15: 68.6 | H15: 100 | P15: 1 | Q15: =IF(P15=1,SUM(F15:M15)+N15,"") -> 250.6 | R15: =IF(AND(P15=1,ISNUMBER(E15)),Q15-E15,"") -> 0 | S15: 0 | T15: Original uploaded workbook
A16: 2022 | B16: 13 | C16: Univ of Washington | D16: Ranked | E16: 249.4 | F16: 66.23 | G16: 73.2 | H16: 110 | P16: 1 | Q16: =IF(P16=1,SUM(F16:M16)+N16,"") -> 249.43 | R16: =IF(AND(P16=1,ISNUMBER(E16)),Q16-E16,"") -> 0.03 | S16: 0 | T16: Original uploaded workbook
A17: 2022 | B17: 14 | C17: Univ of Manitoba | D17: Ranked | E17: 225.7 | F17: 82.45 | G17: 68.3 | H17: 40 | J17: 3.5 | K17: 6.5 | L17: 25 | P17: 1 | Q17: =IF(P17=1,SUM(F17:M17)+N17,"") -> 225.75 | R17: =IF(AND(P17=1,ISNUMBER(E17)),Q17-E17,"") -> 0.05 | S17: 0 | T17: Original uploaded workbook
A18: 2022 | B18: 15 | C18: Ryerson Univ | D18: Ranked | E18: 212.4 | F18: 77.44 | G18: 75 | H18: 60 | P18: 1 | Q18: =IF(P18=1,SUM(F18:M18)+N18,"") -> 212.44 | R18: =IF(AND(P18=1,ISNUMBER(E18)),Q18-E18,"") -> 0.04 | S18: 0 | T18: Original uploaded workbook
A19: 2022 | B19: 16 | C19: Univ of New Mexico | D19: Ranked | E19: 209.7 | F19: 69.21 | G19: 70.5 | H19: 70 | P19: 1 | Q19: =IF(P19=1,SUM(F19:M19)+N19,"") -> 209.71 | R19: =IF(AND(P19=1,ISNUMBER(E19)),Q19-E19,"") -> 0.01 | S19: 0 | T19: Original uploaded workbook
A20: 2022 | B20: 17 | C20: Western Washington Univ | D20: Ranked | E20: 205.3 | F20: 54.68 | G20: 60.6 | H20: 90 | P20: 1 | Q20: =IF(P20=1,SUM(F20:M20)+N20,"") -> 205.28 | R20: =IF(AND(P20=1,ISNUMBER(E20)),Q20-E20,"") -> -0.02 | S20: 0 | T20: Original uploaded workbook
A21: 2022 | B21: 18 | C21: Cornell Univ | D21: Ranked | E21: 199.9 | F21: 44.69 | G21: 65.2 | H21: 90 | P21: 1 | Q21: =IF(P21=1,SUM(F21:M21)+N21,"") -> 199.89 | R21: =IF(AND(P21=1,ISNUMBER(E21)),Q21-E21,"") -> -0.01 | S21: 0 | T21: Original uploaded workbook
A22: 2022 | B22: 19 | C22: Univ of Minnesota - Twin Cities | D22: Ranked | E22: 196.4 | F22: 80.23 | G22: 46.2 | H22: 80 | N22: -10 | P22: 1 | Q22: =IF(P22=1,SUM(F22:M22)+N22,"") -> 196.43 | R22: =IF(AND(P22=1,ISNUMBER(E22)),Q22-E22,"") -> 0.03 | S22: 0 | T22: Original uploaded workbook
